2018-06-02 21:47:21,484 DEBUG    root            Loaded Command Group: [u'gcloud', u'compute', u'firewall_rules']
2018-06-02 21:47:21,493 DEBUG    root            Loaded Command Group: [u'gcloud', u'compute', u'firewall-rules', u'create']
2018-06-02 21:47:21,497 DEBUG    root            Running [gcloud.compute.firewall-rules.create] with arguments: [--allow: "[u'tcp:443']", --description: "Incoming https allowed.", NAME: "allow-https"]
2018-06-02 21:47:21,618 INFO     ___FILE_ONLY___ Creating firewall...
2018-06-02 21:47:22,620 DEBUG    root            (gcloud.compute.firewall-rules.create) Could not fetch resource:
 - The resource 'projects/devops-203203/global/firewalls/allow-https' already exists
Traceback (most recent call last):
  File "/usr/lib64/google-cloud-sdk/lib/googlecloudsdk/calliope/cli.py", line 844, in Execute
    resources = calliope_command.Run(cli=self, args=args)
  File "/usr/lib64/google-cloud-sdk/lib/googlecloudsdk/calliope/backend.py", line 756, in Run
    resources = command_instance.Run(args)
  File "/usr/lib64/google-cloud-sdk/lib/surface/compute/firewall_rules/create.py", line 117, in Run
    request)])
  File "/usr/lib64/google-cloud-sdk/lib/googlecloudsdk/api_lib/compute/client_adapter.py", line 93, in MakeRequests
    errors, error_message='Could not fetch resource:')
  File "/usr/lib64/google-cloud-sdk/lib/googlecloudsdk/api_lib/compute/utils.py", line 108, in RaiseToolException
    RaiseException(problems, calliope_exceptions.ToolException, error_message)
  File "/usr/lib64/google-cloud-sdk/lib/googlecloudsdk/api_lib/compute/utils.py", line 120, in RaiseException
    errors))
ToolException: Could not fetch resource:
 - The resource 'projects/devops-203203/global/firewalls/allow-https' already exists

2018-06-02 21:47:22,621 ERROR    root            (gcloud.compute.firewall-rules.create) Could not fetch resource:
 - The resource 'projects/devops-203203/global/firewalls/allow-https' already exists

