2018-06-01 03:48:10,881 DEBUG    root            Loaded Command Group: [u'gcloud', u'compute', u'instances']
2018-06-01 03:48:10,891 DEBUG    root            Loaded Command Group: [u'gcloud', u'compute', u'instances', u'create']
2018-06-01 03:48:10,899 DEBUG    root            Running [gcloud.compute.instances.create] with arguments: [--image-family: "centos-7", --image-project: "centos-cloud", --machine-type: "f1-micro", --scopes: "[u'cloud-platform']", INSTANCE_NAMES:1: "[u'cacti-server']"]
2018-06-01 03:48:11,497 DEBUG    root            (gcloud.compute.instances.create) Could not fetch resource:
 - The resource 'projects/devops-203203/zones/us-west1-a/instances/cacti-server' already exists
Traceback (most recent call last):
  File "/usr/lib64/google-cloud-sdk/lib/googlecloudsdk/calliope/cli.py", line 844, in Execute
    resources = calliope_command.Run(cli=self, args=args)
  File "/usr/lib64/google-cloud-sdk/lib/googlecloudsdk/calliope/backend.py", line 756, in Run
    resources = command_instance.Run(args)
  File "/usr/lib64/google-cloud-sdk/lib/surface/compute/instances/create.py", line 462, in Run
    return compute_client.MakeRequests(requests)
  File "/usr/lib64/google-cloud-sdk/lib/googlecloudsdk/api_lib/compute/client_adapter.py", line 93, in MakeRequests
    errors, error_message='Could not fetch resource:')
  File "/usr/lib64/google-cloud-sdk/lib/googlecloudsdk/api_lib/compute/utils.py", line 108, in RaiseToolException
    RaiseException(problems, calliope_exceptions.ToolException, error_message)
  File "/usr/lib64/google-cloud-sdk/lib/googlecloudsdk/api_lib/compute/utils.py", line 120, in RaiseException
    errors))
ToolException: Could not fetch resource:
 - The resource 'projects/devops-203203/zones/us-west1-a/instances/cacti-server' already exists

2018-06-01 03:48:11,498 ERROR    root            (gcloud.compute.instances.create) Could not fetch resource:
 - The resource 'projects/devops-203203/zones/us-west1-a/instances/cacti-server' already exists

